تفاوت زمانی آشکار می‌شود که ما درون یک تابع به کد نگاه کنیم.

اگر یک «پرش به بیرون» از `try...catch` وجود داشته باشد، رفتار متفاوت است.

برای مثال، زمانی که یک `return` درون `try...catch` وجود دارد. بند `finally` در صورت *هر گونه* خارج شدن از `try...catch` کار می‌کند حتی با دستور `return`: درست بعد تمام شدن `try...catch` اما قبل از اینکه کد فراخوانی شده کنترل را به دست بگیرد.

```js run
function f() {
  try {
    alert('شروع');
*!*
    return "نتیجه";
*/!*
  } catch (err) {
    /// ...
  } finally {
    alert('پاک سازی!');
  }
}

f(); // !پاک سازی
```

...یا زمانی که یک `throw` وجود داشته باشد، مثل اینجا:

```js run
function f() {
  try {
    alert('شروع');
    throw new Error("یک ارور");
  } catch (err) {
    // ...
    if("نمی‌توانی ارور را مدیریت کنی") {
*!*
      throw err;
*/!*
    }

  } finally {
    alert('پاک سازی!')
  }
}

f(); // !پاک سازی
```

این `finally` است که در اینجا پاک سازی را تضمین می‌کند. اگر ما فقط کد را در انتهای `f` قرار دهیم، در این موقعیت‌ها اجرا نمی‌شود.
